<?xml version="1.0"?>
<robot xmlns:xacro="http://www.ros.org/wiki/xacro" name="CORVUS-Arm">

  <xacro:property name="M_PI"    value="3.1415926535897931" />
  <xacro:property name="D_A2_A3" value="0.34985" />
  <xacro:property name="D_A3_A5" value="0.398" />
  <xacro:property name="J0_MAX"  value="2.1" /> <!-- This was 2.275 in the C++ code, but I think that was wrong. -JJO -->

  <xacro:macro name="gray_box" params="name lx ly lz mass *origin">
    <link name="${name}">
      <visual>
        <xacro:insert_block name="origin" />
        <geometry>
          <box size="${lx} ${ly} ${lz}"/>
        </geometry>
        <material name="dark_gray">
          <color rgba="0.1 0.1 0.1 1"/>
        </material>
      </visual>
      <collision>
        <xacro:insert_block name="origin" />
        <geometry>
          <box size="${lx} ${ly} ${lz}"/>
        </geometry>
      </collision>
      <inertial>
        <origin xyz="0 0 0" rpy="0 0 0"/>
        <mass value="${mass}"/>
        <inertia
          ixx="${mass/12*(ly*ly+lz*lz)}" ixy="00.00" ixz="00.00"
          iyy="${mass/12*(lx*lx+lz*lz)}" iyz="00.00"
          izz="${mass/12*(lx*lx+ly*ly)}"/>
      </inertial>
    </link>
  </xacro:macro>


  <link name="corvus_base">
  </link>
  
  <link name="corvus_or_table">
    <visual>
      <origin xyz="0 0 0" rpy="0 0 ${-M_PI / 2}" />
      <geometry>
        <mesh filename="package://corvus_description/meshes/OR_Table/model.dae" />
      </geometry>
    </visual>
    <inertial>
      <origin xyz="0 0 0" rpy="0 0 0"/>
      <mass value="100.0"/>
      <inertia
        ixx="36.68" ixy="00.00" ixz="00.00"
                    iyy="36.05" iyz="00.42"
                                izz="36.70"/>
    </inertial>
  </link>

  <joint name="or_table_to_base" type="fixed">
    <parent link="corvus_base"/>
    <child link="corvus_or_table"/>
  </joint>

  <xacro:macro name="corvus_arm" params="prefix reflect">
    <link name="${prefix}_link_0">
      <visual>
        <origin xyz="-0.1932 0.138 -0.097 " rpy="0 0 ${M_PI / 2}" />
        <geometry>
          <!-- /home/john/github/mrd-ros/src/urdf/corvus_link_0.dae" -->
          <mesh filename="package://corvus_description/meshes/corvus_link_0.dae" />
        </geometry>
      </visual>
      <collision>
        <origin xyz="-0.1932 0.136 -0.0981" rpy="${-M_PI / 2} ${M_PI} ${M_PI / 2}" />
        <geometry>
          <!-- /home/john/github/mrd-ros/src/urdf/corvus_link_0.STL" -->
          <mesh filename="package://corvus_description/meshes/corvus_link_0.STL" />
        </geometry>
      </collision>
      <inertial>
        <origin xyz="0 0 0" rpy="0 0 0"/>
        <mass value="20.65"/>
        <inertia
          ixx="36.68" ixy="00.00" ixz="00.00"
                      iyy="00.05" iyz="00.42"
                                  izz="36.70"/>
      </inertial>
    </link>

    <link name="${prefix}_link_1">
      <visual>
        <origin xyz="0 0 0" rpy="${M_PI / 2} ${M_PI} 0" />
        <geometry>
          <!-- /home/john/github/mrd-ros/src/urdf/corvus_link_1.dae" -->
          <mesh filename="package://corvus_description/meshes/corvus_link_1.dae" />
        </geometry>
      </visual>
      <collision>
        <origin xyz="0 0 0" rpy="${M_PI} 0 0" />
        <geometry>
          <!-- /home/john/github/mrd-ros/src/urdf/corvus_link_1.STL" -->
          <mesh filename="package://corvus_description/meshes/corvus_link_1.STL" />
        </geometry>
      </collision>
      <!-- These numbers are from the Solidworks models, but I haven't checked that the axes are correct: -->
      <inertial>
        <origin xyz="0 0 0" rpy="0 0 0"/>
        <mass value="13.27"/>
        <inertia
          ixx="00.42" ixy="00.09" ixz="00.00"
                      iyy="00.14" iyz="00.00"
                                  izz="00.49"/>
      </inertial>
    </link>

    <link name="${prefix}_link_2">
      <visual>
        <origin xyz="0 0 0" rpy="0 0 ${-M_PI / 2}" />
        <geometry>
          <mesh filename="package://corvus_description/meshes/corvus_link_2.dae" />
        </geometry>
      </visual>
      <collision>
        <origin xyz="0 0 0" rpy="${M_PI / 2} 0 ${M_PI / 2}" />
        <geometry>
          <mesh filename="package://corvus_description/meshes/corvus_link_2.STL" />
        </geometry>
      </collision>
      <!-- These numbers are from the Solidworks models, but I haven't checked that the axes are correct: -->
      <inertial>
        <origin xyz="0 0 0" rpy="0 0 0"/>
        <mass value="5.80"/>
        <inertia
          ixx="00.02" ixy="00.00"  ixz="00.00"
                      iyy="00.019" iyz="00.00"
                                   izz="00.015"/>
      </inertial>
    </link>

    <link name="${prefix}_link_3">
      <visual>
        <origin xyz="0 0 0" rpy="${-M_PI / 2} ${M_PI} 0" />
        <geometry>
          <mesh filename="package://corvus_description/meshes/corvus_link_3.dae" />
        </geometry>
      </visual>
      <collision>
        <origin xyz="0 0 0" rpy="0 0 0" />
        <geometry>
          <mesh filename="package://corvus_description/meshes/corvus_link_3.STL" />
        </geometry>
      </collision>
      <!-- These numbers are from the Solidworks models, but I haven't checked that the axes are correct: -->
      <inertial>
        <origin xyz="0 0 0" rpy="0 0 0"/>
        <mass value="7.40"/>
        <inertia
          ixx="00.76" ixy="00.01" ixz="00.00"
                      iyy="00.03" iyz="-0.06"
                                  izz="00.75"/>
      </inertial>
    </link>

    <link name="${prefix}_link_4">
      <visual>
        <origin xyz="0 0 0" rpy="${-M_PI / 2} ${M_PI} 0" />
        <geometry>
          <!-- /home/john/github/mrd-ros/src/urdf/corvus_link_4.dae" -->
          <mesh filename="package://corvus_description/meshes/corvus_link_4.dae" />
        </geometry>
      </visual>
      <collision>
        <origin xyz="0 0 0" rpy="0 0 0" />
        <geometry>
          <!-- /home/john/github/mrd-ros/src/urdf/corvus_link_4.STL" -->
          <mesh filename="package://corvus_description/meshes/corvus_link_4.STL" />
        </geometry>
      </collision>
      <!-- These numbers are from the Solidworks models, but I haven't checked that the axes are correct: -->
      <inertial>
        <origin xyz="0 0 0" rpy="0 0 0"/>
        <mass value="2.65"/>
        <inertia
          ixx="0.074" ixy="00.00" ixz="00.00"
                      iyy="0.007" iyz="00.00"
                                  izz="0.071"/>
      </inertial>
    </link>

    <link name="${prefix}_link_5">
      <visual>
        <origin xyz="0 0 0" rpy="0 ${M_PI} ${M_PI}" />
        <geometry>
          <!-- /home/john/github/mrd-ros/src/urdf/corvus_link_5.dae" -->
          <mesh filename="package://corvus_description/meshes/corvus_link_5.dae" />
        </geometry>
      </visual>
      <collision>
        <origin xyz="0 0 0" rpy="${-M_PI / 2} 0 ${M_PI}" />
        <geometry>
          <!-- /home/john/github/mrd-ros/src/urdf/corvus_link_5.STL" -->
          <mesh filename="package://corvus_description/meshes/corvus_link_5.STL" />
        </geometry>
      </collision>
      <!-- These numbers are from the Solidworks models, but I haven't checked that the axes are correct: -->
      <inertial>
        <origin xyz="0 0 0" rpy="0 0 0"/>
        <mass value="2.29"/>
        <inertia
          ixx="0.015" ixy="0.000" ixz="0.000"
                      iyy="0.004" iyz="0.001"
                                  izz="0.015"/>
      </inertial>
    </link>

    <link name="${prefix}_link_6">
      <visual>
        <origin xyz="0 0 0" rpy="0 ${M_PI / 2} 0" />
        <geometry>
          <!-- /home/john/github/mrd-ros/src/urdf/corvus_link_6.dae" -->
          <mesh filename="package://corvus_description/meshes/corvus_link_6.dae" />
        </geometry>
      </visual>
      <collision>
        <origin xyz="0 0 0" rpy="0 ${-M_PI / 2} 0" />
        <geometry>
          <!-- /home/john/github/mrd-ros/src/urdf/corvus_link_6.STL" -->
          <mesh filename="package://corvus_description/meshes/corvus_link_6.STL" />
        </geometry>
      </collision>
      <!-- These numbers are from the Solidworks models, but I haven't checked that the axes are correct: -->
      <inertial>
        <origin xyz="0 0 0" rpy="0 0 0"/>
        <mass value="0.396"/>
        <inertia
          ixx="0.00270" ixy="0.00000" ixz="0.00000"
                        iyy="0.02364" iyz="0.00000"
                                      izz="0.02364"/>
      </inertial>
    </link>

    <joint name="${prefix}_arm_to_base" type="fixed">
      <parent link="corvus_base"/>
      <child link="${prefix}_link_0"/>
      <origin xyz="${reflect * (0.1505+.611/2)} ${reflect * -J0_MAX / 2 } ${.600}" rpy="${M_PI / 2} ${M_PI} ${(reflect+1) / 2 * M_PI}" />
    </joint>

    <joint name="${prefix}_joint_0" type="prismatic">
      <parent link="${prefix}_link_0"/>
      <child link="${prefix}_link_1"/>
      <axis   xyz="0 0 1"/>
      <limit  lower="0" upper="${J0_MAX}" effort="1" velocity="1" />
      <!-- This is a ballpark guess for the AMC linear joint: -->
      <dynamics damping="20.0" friction="10.0"/>
    </joint>

    <joint name="${prefix}_joint_1" type="revolute">
      <parent link="${prefix}_link_1"/>
      <child link="${prefix}_link_2"/>
      <origin xyz="0 0 0" rpy="${M_PI / 2} ${M_PI / 2} 0" />
      <axis   xyz="0 0 1"/>
      <limit  lower="-${M_PI}" upper="${M_PI}" effort="260" velocity="${28 / 60}" />
      <!-- This is a ballpark guess for the Xenus joints: -->
      <dynamics damping="20.0" friction="5.0"/>
    </joint>

    <joint name="${prefix}_joint_2" type="revolute">
      <parent link="${prefix}_link_2"/>
      <child link="${prefix}_link_3"/>
      <origin xyz="0 0 0" rpy="${M_PI / 2} 0 ${M_PI / 2}" />
      <axis   xyz="0 0 1"/>
      <!--limit  lower="-M_PI/3" upper="M_PI/2" effort="260" velocity="28/60" -->
      <limit  lower="${-M_PI / 3}" upper="${M_PI / 2}" effort="260" velocity="${28 / 60}" />
      <!-- This is a ballpark guess for the Xenus joints: -->
      <dynamics damping="20.0" friction="5.0"/>
    </joint>

    <joint name="${prefix}_joint_3" type="revolute">
      <parent link="${prefix}_link_3"/>
      <child link="${prefix}_link_4"/>
      <origin xyz="0 ${D_A2_A3} 0" rpy="0 0 0" />
      <axis   xyz="0 0 1"/>
      <!--limit  lower="-M_PI/2" upper="M_PI*5/6" effort="260" velocity="28/60" -->
      <limit  lower="${-M_PI / 2}" upper="${M_PI * 5 / 6}" effort="260" velocity="${28 / 60}" />
      <!-- This is a ballpark guess for the Xenus joints: -->
      <dynamics damping="20.0" friction="5.0"/>
    </joint>

    <joint name="${prefix}_joint_4" type="revolute">
      <parent link="${prefix}_link_4"/>
      <child link="${prefix}_link_5"/>
      <origin xyz="0 ${D_A3_A5} 0" rpy="${-M_PI / 2} 0 0" />
      <axis   xyz="0 0 1"/>
      <limit  lower="-${M_PI}" upper="${M_PI}" effort="1" velocity="1" />
      <!-- This is a ballpark guess for the AMC joints: -->
      <dynamics damping="20.0" friction="100.0"/>
    </joint>

    <joint name="${prefix}_joint_5" type="continuous">
      <parent link="${prefix}_link_5"/>
      <child link="${prefix}_link_6"/>
      <origin xyz="0 0 0" rpy="${M_PI / 2} 0 ${-M_PI / 2}" />
      <axis   xyz="0 0 1"/>
      <limit  lower="-${M_PI}" upper="${M_PI}" effort="1" velocity="1" />
      <!-- This is a ballpark guess for the AMC joints: -->
      <dynamics damping="20.0" friction="100.0"/>
    </joint>

  </xacro:macro>

  <xacro:macro name="servo_gripper_claw" params="prefix reflect">

    <link name="servo_gripper_link_driver_${prefix}">
      <visual>
        <origin xyz="0 0 0" rpy="${(1-reflect)*M_PI / 2} 0 ${M_PI}" />
        <geometry>
          <mesh filename="package://corvus_description/meshes/servo_gripper_connector.dae" />
        </geometry>
      </visual>
      <collision>
        <origin xyz="0 0 0" rpy="${reflect*M_PI / 2} 0 0" />
        <geometry>
          <mesh filename="package://corvus_description/meshes/servo_gripper_connector.STL" />
        </geometry>
      </collision>
    </link>

    <link name="servo_gripper_link_tooth_${prefix}_upper">
      <visual>
        <origin xyz="0 0 ${((1-reflect)/2)*.00635}" rpy="${M_PI} 0 ${M_PI}" />
        <geometry>
          <mesh filename="package://corvus_description/meshes/servo_gripper_tooth.dae" />
        </geometry>
      </visual>
      <collision>
        <origin xyz="0 0 ${((1-reflect)/2)*.00635}" rpy="${-M_PI / 2} 0 0" />
        <geometry>
          <mesh filename="package://corvus_description/meshes/servo_gripper_tooth.STL" />
        </geometry>
      </collision>
    </link>

    <link name="servo_gripper_link_tooth_${prefix}_lower">
      <visual>
        <origin xyz="0 0 ${((1-reflect)/2)*.00635}" rpy="${M_PI} 0 ${M_PI}" />
        <geometry>
          <mesh filename="package://corvus_description/meshes/servo_gripper_tooth.dae" />
        </geometry>
      </visual>
      <collision>
        <origin xyz="0 0 ${((1-reflect)/2)*.00635}" rpy="${-M_PI / 2} 0 0" />
        <geometry>
          <mesh filename="package://corvus_description/meshes/servo_gripper_tooth.STL" />
        </geometry>
      </collision>
    </link>

    <link name="servo_gripper_link_connector_${prefix}_upper">
      <visual>
        <origin xyz="0 0 0" rpy="${M_PI} 0 ${M_PI}" />
        <geometry>
          <mesh filename="package://corvus_description/meshes/servo_gripper_connector.dae" />
        </geometry>
      </visual>
      <collision>
        <origin xyz="0 0 0" rpy="${-M_PI / 2} 0 0" />
        <geometry>
          <mesh filename="package://corvus_description/meshes/servo_gripper_connector.STL" />
        </geometry>
      </collision>
    </link>

    <link name="servo_gripper_link_connector_${prefix}_lower">
      <visual>
        <origin xyz="0 0 0" rpy="${M_PI} 0 ${M_PI}" />
        <geometry>
          <mesh filename="package://corvus_description/meshes/servo_gripper_connector.dae" />
        </geometry>
      </visual>
      <collision>
        <origin xyz="0 0 0" rpy="${-M_PI / 2} 0 0" />
        <geometry>
          <mesh filename="package://corvus_description/meshes/servo_gripper_connector.STL" />
        </geometry>
      </collision>
    </link>


    <joint name="servo_gripper_servo_${prefix}" type="revolute">
      <parent link="servo_gripper_link_base"/>
      <child link="servo_gripper_link_driver_${prefix}"/>
      <origin xyz="${reflect*0.020} -.0127 0" rpy="${M_PI / 2} 0 ${(1-reflect)*M_PI / 2}" />
      <axis   xyz="0 0 1"/>
      <limit  lower="0" upper="${M_PI/2}" effort="1" velocity="1" />
      <!-- This is a ballpark guess for the AMC joints: -->
      <dynamics damping="20.0" friction="100.0"/>
    </joint>

    <joint name="servo_gripper_tooth_mimic_${prefix}" type="revolute">
      <parent link="servo_gripper_link_driver_${prefix}"/>
      <child link="servo_gripper_link_tooth_${prefix}_upper"/>
      <origin xyz="0.050 0 0" rpy="0 0 ${M_PI / 2}" />
      <axis   xyz="0 0 1"/>
      <limit  lower="-${M_PI}" upper="${M_PI}" effort="1" velocity="1" />
      <mimic  joint="servo_gripper_servo_${prefix}" multiplier="-1" offset="${20*M_PI/180}"/>
      <dynamics damping="20.0" friction="100.0"/>
    </joint>

    <joint name="servo_gripper_tooths_${prefix}" type="fixed">
      <parent link="servo_gripper_link_tooth_${prefix}_upper"/>
      <child link="servo_gripper_link_tooth_${prefix}_lower"/>
      <origin xyz="0 0 ${reflect*(-0.00635)}" rpy="0 0 0" />
      <axis   xyz="0 0 1"/>
      <limit  lower="-${M_PI}" upper="${M_PI}" effort="1" velocity="1" />
    </joint>

    <joint name="servo_gripper_connector_mimic_${prefix}" type="revolute">
      <parent link="servo_gripper_link_tooth_${prefix}_lower"/>
      <child link="servo_gripper_link_connector_${prefix}_upper"/>
      <origin xyz="0.045 0 ${2*0.00635}" rpy="0 0 ${M_PI / 2}" />
      <axis   xyz="0 0 1"/>
      <limit  lower="-${M_PI}" upper="${M_PI}" effort="1" velocity="1" />
      <mimic  joint="servo_gripper_servo_${prefix}" multiplier="1" offset="${-20*M_PI/180}"/>
      <dynamics damping="20.0" friction="100.0"/>
    </joint>

    <joint name="servo_gripper_connectors_${prefix}" type="fixed">
      <parent link="servo_gripper_link_connector_${prefix}_upper"/>
      <child link="servo_gripper_link_connector_${prefix}_lower"/>
      <origin xyz="0 0 ${-3*0.00635}" rpy="0 0 0" />
      <axis   xyz="0 0 1"/>
      <limit  lower="-${M_PI}" upper="${M_PI}" effort="1" velocity="1" />
    </joint>

  </xacro:macro>

  <xacro:macro name="servo_gripper" params="prefix">

    <link name="servo_gripper_link_base">
      <visual>
        <origin xyz="0 0 0" rpy="${M_PI/2} ${M_PI} 0" />
        <geometry>
          <mesh filename="package://corvus_description/meshes/servo_gripper_base.dae" />
        </geometry>
      </visual>
      <collision>
        <origin xyz="0 0 0" rpy="${M_PI} 0 0" />
        <geometry>
          <mesh filename="package://corvus_description/meshes/servo_gripper_base.STL" />
        </geometry>
      </collision>
    </link>

    <joint name="servo_gripper_corvus_to_base" type="fixed">
      <parent link="${prefix}_link_6"/>
      <child link="servo_gripper_link_base"/>
      <origin xyz="0 -0.0323 ${0.0299+0.1073}" rpy="0 0 0" />
    </joint>

    <xacro:servo_gripper_claw prefix="right"  reflect="1" />
    <xacro:servo_gripper_claw prefix="left"  reflect="-1" />

  </xacro:macro>

  <xacro:corvus_arm prefix="green" reflect="1" />
  <xacro:corvus_arm prefix="gold"  reflect="-1" />

  <!-- This attaches an end effector to the gold arm -->
  <!-- Maybe end effectors should be choosable somehow? -->
  <!--xacro:servo_gripper prefix="gold" /-->
</robot>
